<!DOCTYPE html>
<html lang="en">
<head>
    <meta charset="UTF-8">
    <meta http-equiv="X-UA-Compatible" content="IE=edge">
    <meta name="viewport" content="width=device-width, initial-scale=1.0">
    <title>Document</title>
</head>
<body>
    <script>
        /* 
        6.promise异常传/穿透?
          (1)当使用promise的then链式调用时, 可以在最后指定失败的回调, 
          (2)前面任何操作出了异常, 都会传到最后失败的回调中处理
        7.中断promise链?
          (1)当使用promise的then链式调用时, 在中间中断, 不再调用后面的回调函数
          (2)办法: 在回调函数中返回一个pendding状态的promise对象
        */
    
        new Promise((resolve, reject) => {
          // resolve(1)
          reject(1)
        }).then(
          value => {
            console.log('onResolved1()', value)
            return 2
          },
          //若省略失败的的回调函数  则默认为下面的函数
          //可以向后传递异常
          // reason => {throw reason}
          
          //返回一个失败的Promise 可以继续向后传递异常
          reason =>  Promise.reject(reason)
          
          //返回返回一个pendding状态的promise对象 中断promise链
          //reason => new Promise(() => {}) 
          
          //返回一个值 创建新的promise 会终止异常穿透
          //reason => reason
        ).then(
          value => {
            console.log('onResolved2()', value)
            return 3
          },
          reason => {throw reason}
        ).then(
          value => {
            console.log('onResolved3()', value)
            return 4
          },
          reason => Promise.reject(reason)
        ).catch(reason => {
          console.log('onRejected1()', reason)
          // throw reason和return Promise.reject(reason) 可以继续传递异常
         // throw reason
          // return Promise.reject(reason)   
   
         // 返回一个pending的promise  中断promise链
          return new Promise(() => {}) 
        }).then(
          value => {
            console.log('onResolved3()', value)
          },
          reason => {
            console.log('onRejected2()', reason)
          }
        )
    
      </script>
</body>
</html>